Workbook

Sheet Leads
A1: # | B1: Sector | C1: Negocio | D1: Localidad | E1: Dirección | F1: Teléfono | G1: WhatsApp | H1: Enlace WhatsApp | I1: Mensaje sugerido | J1: Estado | K1: Notas
A2: 1 | B2: Fisioterapia | C2: Fontanet Medicina i Fisioterapia | D2: Tarragona | E2: C/ Gasòmetre, 24 | F2: 977 22 69 00 | G2: No (fijo: llamar) | I2: Hola! Soy Marcos, de Tarragona. He leído la web de Fontanet Medicina i Fisioterapia y he reescrito vuestro texto de presentación para que convenza más a quien la visita. ¿Os lo envío gratis para que lo veáis? | J2: Pendiente
A3: 2 | B3: Fisioterapia | C3: Fisioteràpia Núria Barcelona | D3: Tarragona | E3: Rambla Nova, 78, 1º1ª B | F3: 977 24 11 18 | G3: No (fijo: llamar) | I3: Hola! Soy Marcos, de Tarragona. He leído la web de Fisioteràpia Núria Barcelona y he reescrito vuestro texto de presentación para que convenza más a quien la visita. ¿Os lo envío gratis para que lo veáis? | J3: Pendiente
A4: 3 | B4: Fisioterapia | C4: FisioVitalTGN | D4: Tarragona | E4: Av. de Roma, 14, Entl. 3a | F4: 977 21 34 68 | G4: No (fijo: llamar) | I4: Hola! Soy Marcos, de Tarragona. He leído la web de FisioVitalTGN y he reescrito vuestro texto de presentación para que convenza más a quien la visita. ¿Os lo envío gratis para que lo veáis? | J4: Pendiente
A5: 4 | B5: Fisioterapia | C5: Tonus Fisioteràpia | D5: Tarragona | E5: C/ Mercè Rodoreda, 2 | F5: 977 29 07 26 | G5: No (fijo: llamar) | I5: Hola! Soy Marcos, de Tarragona. He leído la web de Tonus Fisioteràpia y he reescrito vuestro texto de presentación para que convenza más a quien la visita. ¿Os lo envío gratis para que lo veáis? | J5: Pendiente
A6: 5 | B6: Fisioterapia | C6: Carlos del Egido Fisioterapeuta | D6: Tarragona | E6: C/ Sant Llorenç, 12, 1º1ª | F6: 629 328 606 | G6: Sí (móvil) | H6: https://wa.me/34629328606 | I6: Hola! Soy Marcos, de Tarragona. He leído la web de Carlos del Egido Fisioterapeuta y he reescrito vuestro texto de presentación para que convenza más a quien la visita. ¿Os lo envío gratis para que lo veáis? | J6: Pendiente
A7: 6 | B7: Fisioterapia | C7: Balance Montiel | D7: Tarragona | E7: C/ Lleida, 20, 2º2ª B | F7: 671 962 498 | G7: Sí (móvil) | H7: https://wa.me/34671962498 | I7: Hola! Soy Marcos, de Tarragona. He leído la web de Balance Montiel y he reescrito vuestro texto de presentación para que convenza más a quien la visita. ¿Os lo envío gratis para que lo veáis? | J7: Pendiente
A8: 7 | B8: Fisioterapia | C8: Sinapfis Fisioteràpia | D8: Tarragona | E8: C/ Riu Tordera, local 3 | F8: 613 54 59 45 | G8: Sí (móvil) | H8: https://wa.me/34613545945 | I8: Hola! Soy Marcos, de Tarragona. He leído la web de Sinapfis Fisioteràpia y he reescrito vuestro texto de presentación para que convenza más a quien la visita. ¿Os lo envío gratis para que lo veáis? | J8: Pendiente
A9: 8 | B9: Fisioterapia | C9: Adrià Adam Dasca Fisioterapeuta | D9: Tarragona | E9: Av. Catalunya, 22D, entlo. 1ª | F9: 646 74 34 10 | G9: Sí (móvil) | H9: https://wa.me/34646743410 | I9: Hola! Soy Marcos, de Tarragona. He leído la web de Adrià Adam Dasca Fisioterapeuta y he reescrito vuestro texto de presentación para que convenza más a quien la visita. ¿Os lo envío gratis para que lo veáis? | J9: Pendiente
A10: 9 | B10: Fisioterapia | C10: Claudia Ardid Fisioterapia | D10: Tarragona | E10: C/ Cardenal Cervantes, 23, bajos B | F10: 618 44 82 33 | G10: Sí (móvil) | H10: https://wa.me/34618448233 | I10: Hola! Soy Marcos, de Tarragona. He leído la web de Claudia Ardid Fisioterapia y he reescrito vuestro texto de presentación para que convenza más a quien la visita. ¿Os lo envío gratis para que lo veáis? | J10: Pendiente
A11: 10 | B11: Fisioterapia | C11: Eric Vicens Centre de Fisioteràpia | D11: Tarragona | E11: C/ Higini Anglès, 4, local 18 | F11: 615 23 29 00 | G11: Sí (móvil) | H11: https://wa.me/34615232900 | I11: Hola! Soy Marcos, de Tarragona. He leído la web de Eric Vicens Centre de Fisioteràpia y he reescrito vuestro texto de presentación para que convenza más a quien la visita. ¿Os lo envío gratis para que lo veáis? | J11: Pendiente
A12: 11 | B12: Fisioterapia | C12: Fisioreus | D12: Reus | E12: C/ Felip Pedrell i Sabaté, 5 | F12: 977 07 42 81 | G12: No (fijo: llamar) | I12: Hola! Soy Marcos, de Tarragona. He leído la web de Fisioreus y he reescrito vuestro texto de presentación para que convenza más a quien la visita. ¿Os lo envío gratis para que lo veáis? | J12: Pendiente
A13: 12 | B13: Fisioterapia | C13: Fisiorecupera't | D13: Reus | E13: C/ Ample, 62 | F13: 635 054 064 | G13: Sí (móvil) | H13: https://wa.me/34635054064 | I13: Hola! Soy Marcos, de Tarragona. He leído la web de Fisiorecupera't y he reescrito vuestro texto de presentación para que convenza más a quien la visita. ¿Os lo envío gratis para que lo veáis? | J13: Pendiente
A14: 13 | B14: Fisioterapia | C14: Fisioterapia Vilafortuny | D14: Cambrils | E14: Vilafortuny | F14: 977 36 20 10 | G14: No (fijo: llamar) | I14: Hola! Soy Marcos, de Tarragona. He leído la web de Fisioterapia Vilafortuny y he reescrito vuestro texto de presentación para que convenza más a quien la visita. ¿Os lo envío gratis para que lo veáis? | J14: Pendiente
A15: 14 | B15: Fisioterapia | C15: Axis Centro de Fisioterapia | D15: Cambrils | E15: C/ Sant Josep, 15 | F15: 977 79 54 33 | G15: No (fijo: llamar) | I15: Hola! Soy Marcos, de Tarragona. He leído la web de Axis Centro de Fisioterapia y he reescrito vuestro texto de presentación para que convenza más a quien la visita. ¿Os lo envío gratis para que lo veáis? | J15: Pendiente
A16: 15 | B16: Fisioterapia | C16: Cenfis Funcional | D16: Cambrils | E16: C/ Santa Joaquina de Vedruna, 4 | F16: 977 79 22 55 | G16: No (fijo: llamar) | I16: Hola! Soy Marcos, de Tarragona. He leído la web de Cenfis Funcional y he reescrito vuestro texto de presentación para que convenza más a quien la visita. ¿Os lo envío gratis para que lo veáis? | J16: Pendiente
A17: 16 | B17: Fisioterapia | C17: Fisiosalou | D17: Salou | E17: C/ Montsant, 2 | F17: 977 35 09 87 | G17: No (fijo: llamar) | I17: Hola! Soy Marcos, de Tarragona. He leído la web de Fisiosalou y he reescrito vuestro texto de presentación para que convenza más a quien la visita. ¿Os lo envío gratis para que lo veáis? | J17: Pendiente
A18: 17 | B18: Abogados | C18: Baiges Advocats | D18: Tarragona | E18: C/ Lleida, 22 | F18: 659 103 572 | G18: Sí (móvil) | H18: https://wa.me/34659103572 | I18: Hola! Soy Marcos, de Tarragona. He leído la web de Baiges Advocats y he reescrito vuestro texto de presentación para que convenza más a quien la visita. ¿Os lo envío gratis para que lo veáis? | J18: Pendiente
A19: 18 | B19: Abogados | C19: Curto Abogados | D19: Tarragona | E19: C/ Mossèn Salvador Ritort i Faus, 27 | F19: 977 22 35 22 | G19: No (fijo: llamar) | I19: Hola! Soy Marcos, de Tarragona. He leído la web de Curto Abogados y he reescrito vuestro texto de presentación para que convenza más a quien la visita. ¿Os lo envío gratis para que lo veáis? | J19: Pendiente
A20: 19 | B20: Abogados | C20: Vives i Tous Advocats | D20: Tarragona | E20: C/ August, 12, 1º | F20: 977 23 02 24 | G20: No (fijo: llamar) | I20: Hola! Soy Marcos, de Tarragona. He leído la web de Vives i Tous Advocats y he reescrito vuestro texto de presentación para que convenza más a quien la visita. ¿Os lo envío gratis para que lo veáis? | J20: Pendiente
A21: 20 | B21: Gestoría | C21: Gestoría Riola | D21: Tarragona | E21: Rambla Nova, 110, 2º2ª | F21: 977 24 17 07 | G21: No (fijo: llamar) | I21: Hola! Soy Marcos, de Tarragona. He leído la web de Gestoría Riola y he reescrito vuestro texto de presentación para que convenza más a quien la visita. ¿Os lo envío gratis para que lo veáis? | J21: Pendiente
A22: 21 | B22: Gestoría | C22: Sugranyes Assessors | D22: Tarragona | E22: C/ Sant Francesc, 10 | F22: 977 23 38 06 | G22: No (fijo: llamar) | I22: Hola! Soy Marcos, de Tarragona. He leído la web de Sugranyes Assessors y he reescrito vuestro texto de presentación para que convenza más a quien la visita. ¿Os lo envío gratis para que lo veáis? | J22: Pendiente
A23: 22 | B23: Gestoría | C23: Mallol Assessors | D23: Tarragona | E23: C/ Pere Martell, 53 | F23: 977 23 57 52 | G23: No (fijo: llamar) | I23: Hola! Soy Marcos, de Tarragona. He leído la web de Mallol Assessors y he reescrito vuestro texto de presentación para que convenza más a quien la visita. ¿Os lo envío gratis para que lo veáis? | J23: Pendiente
A24: 23 | B24: Gestoría | C24: ENTarragona Asesores | D24: Tarragona | E24: C/ Pare Palau, 5, entl. 3 | F24: 644 646 221 | G24: Sí (móvil) | H24: https://wa.me/34644646221 | I24: Hola! Soy Marcos, de Tarragona. He leído la web de ENTarragona Asesores y he reescrito vuestro texto de presentación para que convenza más a quien la visita. ¿Os lo envío gratis para que lo veáis? | J24: Pendiente
A25: 24 | B25: Gestoría | C25: Jondal Assessors | D25: Tarragona | E25: Bloc Coll de Lilla, local 2ª | F25: 977 20 17 03 | G25: No (fijo: llamar) | I25: Hola! Soy Marcos, de Tarragona. He leído la web de Jondal Assessors y he reescrito vuestro texto de presentación para que convenza más a quien la visita. ¿Os lo envío gratis para que lo veáis? | J25: Pendiente
A26: 25 | B26: Gestoría | C26: Llurba Assessoria | D26: Tarragona | E26: Rambla Nova, 108, entl. 5 | F26: 977 24 24 78 | G26: No (fijo: llamar) | I26: Hola! Soy Marcos, de Tarragona. He leído la web de Llurba Assessoria y he reescrito vuestro texto de presentación para que convenza más a quien la visita. ¿Os lo envío gratis para que lo veáis? | J26: Pendiente
A27: 26 | B27: Gestoría | C27: Gestoría Boronat | D27: Tarragona | E27: Rambla Nova, 80 | F27: 977 23 82 06 | G27: No (fijo: llamar) | I27: Hola! Soy Marcos, de Tarragona. He leído la web de Gestoría Boronat y he reescrito vuestro texto de presentación para que convenza más a quien la visita. ¿Os lo envío gratis para que lo veáis? | J27: Pendiente
A28: 27 | B28: Gestoría | C28: Tarracogest (Asesoría Pérez) | D28: Tarragona | E28: C/ August, 5, 3º1ª | F28: 977 24 30 38 | G28: No (fijo: llamar) | I28: Hola! Soy Marcos, de Tarragona. He leído la web de Tarracogest (Asesoría Pérez) y he reescrito vuestro texto de presentación para que convenza más a quien la visita. ¿Os lo envío gratis para que lo veáis? | J28: Pendiente
A29: 28 | B29: Dentista | C29: Clínica Dental Dra. Lorena Montes | D29: Tarragona | E29: C/ Higini Anglès, 10 | F29: 977 21 99 82 | G29: No (fijo: llamar) | I29: Hola! Soy Marcos, de Tarragona. He leído la web de Clínica Dental Dra. Lorena Montes y he reescrito vuestro texto de presentación para que convenza más a quien la visita. ¿Os lo envío gratis para que lo veáis? | J29: Pendiente
A30: 29 | B30: Dentista | C30: Clínica Dental Dr. Sergi Ibern | D30: Tarragona | E30: Rambla Nova, 123 | F30: 977 21 88 47 | G30: No (fijo: llamar) | I30: Hola! Soy Marcos, de Tarragona. He leído la web de Clínica Dental Dr. Sergi Ibern y he reescrito vuestro texto de presentación para que convenza más a quien la visita. ¿Os lo envío gratis para que lo veáis? | J30: Pendiente
A31: 30 | B31: Dentista | C31: Clínica Dental Dr. Tello | D31: Tarragona | E31: C/ Comte de Rius, 16 | F31: 977 23 94 02 | G31: No (fijo: llamar) | I31: Hola! Soy Marcos, de Tarragona. He leído la web de Clínica Dental Dr. Tello y he reescrito vuestro texto de presentación para que convenza más a quien la visita. ¿Os lo envío gratis para que lo veáis? | J31: Pendiente
A32: 31 | B32: Dentista | C32: Orthoclinic Tarragona | D32: Tarragona | E32: Av. Catalunya, 22 | F32: 977 23 59 76 | G32: No (fijo: llamar) | I32: Hola! Soy Marcos, de Tarragona. He leído la web de Orthoclinic Tarragona y he reescrito vuestro texto de presentación para que convenza más a quien la visita. ¿Os lo envío gratis para que lo veáis? | J32: Pendiente
A33: 32 | B33: Dentista | C33: IB Clínica Dental | D33: Tarragona | E33: C/ Mossèn Salvador Ritort i Faus, 25B | F33: 977 23 71 28 | G33: No (fijo: llamar) | I33: Hola! Soy Marcos, de Tarragona. He leído la web de IB Clínica Dental y he reescrito vuestro texto de presentación para que convenza más a quien la visita. ¿Os lo envío gratis para que lo veáis? | J33: Pendiente
A34: 33 | B34: Dentista | C34: Clínica Curull | D34: Tarragona | E34: Rambla Nova, 114 | F34: 977 24 13 80 | G34: No (fijo: llamar) | I34: Hola! Soy Marcos, de Tarragona. He leído la web de Clínica Curull y he reescrito vuestro texto de presentación para que convenza más a quien la visita. ¿Os lo envío gratis para que lo veáis? | J34: Pendiente
A35: 34 | B35: Dentista | C35: Noguera Clínica Dental | D35: Tarragona | E35: C/ Pare Palau, 5, entl. | F35: 977 22 16 14 | G35: No (fijo: llamar) | I35: Hola! Soy Marcos, de Tarragona. He leído la web de Noguera Clínica Dental y he reescrito vuestro texto de presentación para que convenza más a quien la visita. ¿Os lo envío gratis para que lo veáis? | J35: Pendiente
A36: 35 | B36: Dentista | C36: Clínica Dental A. Boronat | D36: Tarragona | E36: Rambla Nova, 80 | F36: 977 23 77 18 | G36: No (fijo: llamar) | I36: Hola! Soy Marcos, de Tarragona. He leído la web de Clínica Dental A. Boronat y he reescrito vuestro texto de presentación para que convenza más a quien la visita. ¿Os lo envío gratis para que lo veáis? | J36: Pendiente
A37: 36 | B37: Dentista | C37: Lasdent | D37: Tarragona | E37: C/ Francesc Bastos, 18 | F37: 977 22 69 07 | G37: No (fijo: llamar) | I37: Hola! Soy Marcos, de Tarragona. He leído la web de Lasdent y he reescrito vuestro texto de presentación para que convenza más a quien la visita. ¿Os lo envío gratis para que lo veáis? | J37: Pendiente
A38: 37 | B38: Psicología | C38: Centro Psicológico Torguet | D38: Tarragona | E38: Rambla Nova, 96 | F38: 607 23 07 01 | G38: Sí (móvil) | H38: https://wa.me/34607230701 | I38: Hola! Soy Marcos, de Tarragona. He leído la web de Centro Psicológico Torguet y he reescrito vuestro texto de presentación para que convenza más a quien la visita. ¿Os lo envío gratis para que lo veáis? | J38: Pendiente
A39: 38 | B39: Psicología | C39: SN Psicología | D39: Tarragona | E39: Rambla Nova, 21 | F39: 654 07 56 38 | G39: Sí (móvil) | H39: https://wa.me/34654075638 | I39: Hola! Soy Marcos, de Tarragona. He leído la web de SN Psicología y he reescrito vuestro texto de presentación para que convenza más a quien la visita. ¿Os lo envío gratis para que lo veáis? | J39: Pendiente
A40: 39 | B40: Psicología | C40: Psicólogos Tarragona | D40: Tarragona | E40: Via de l'Imperi Romà | F40: 670 68 86 05 | G40: Sí (móvil) | H40: https://wa.me/34670688605 | I40: Hola! Soy Marcos, de Tarragona. He leído la web de Psicólogos Tarragona y he reescrito vuestro texto de presentación para que convenza más a quien la visita. ¿Os lo envío gratis para que lo veáis? | J40: Pendiente
...

Sheet Resumen
A1: Sector | B1: Nº leads | C1: Con WhatsApp
A2: Abogados | B2: =COUNTIF(Leads!B:B,"Abogados") | C2: =COUNTIFS(Leads!B:B,"Abogados",Leads!G:G,"Sí*")
A3: Academia | B3: =COUNTIF(Leads!B:B,"Academia") | C3: =COUNTIFS(Leads!B:B,"Academia",Leads!G:G,"Sí*")
A4: Autoescuela | B4: =COUNTIF(Leads!B:B,"Autoescuela") | C4: =COUNTIFS(Leads!B:B,"Autoescuela",Leads!G:G,"Sí*")
A5: Dentista | B5: =COUNTIF(Leads!B:B,"Dentista") | C5: =COUNTIFS(Leads!B:B,"Dentista",Leads!G:G,"Sí*")
A6: Entrenador/Gym | B6: =COUNTIF(Leads!B:B,"Entrenador/Gym") | C6: =COUNTIFS(Leads!B:B,"Entrenador/Gym",Leads!G:G,"Sí*")
A7: Estética/Peluquería | B7: =COUNTIF(Leads!B:B,"Estética/Peluquería") | C7: =COUNTIFS(Leads!B:B,"Estética/Peluquería",Leads!G:G,"Sí*")
A8: Fisioterapia | B8: =COUNTIF(Leads!B:B,"Fisioterapia") | C8: =COUNTIFS(Leads!B:B,"Fisioterapia",Leads!G:G,"Sí*")
A9: Gestoría | B9: =COUNTIF(Leads!B:B,"Gestoría") | C9: =COUNTIFS(Leads!B:B,"Gestoría",Leads!G:G,"Sí*")
A10: Inmobiliaria | B10: =COUNTIF(Leads!B:B,"Inmobiliaria") | C10: =COUNTIFS(Leads!B:B,"Inmobiliaria",Leads!G:G,"Sí*")
A11: Psicología | B11: =COUNTIF(Leads!B:B,"Psicología") | C11: =COUNTIFS(Leads!B:B,"Psicología",Leads!G:G,"Sí*")
A12: Taller | B12: =COUNTIF(Leads!B:B,"Taller") | C12: =COUNTIFS(Leads!B:B,"Taller",Leads!G:G,"Sí*")
A13: TOTAL | B13: =SUM(B2:B12) | C13: =SUM(C2:C12)
